Workbook
Name ExpenseCats: Master_Data!$D$8:$D$27
Name IncomeCats: Master_Data!$C$8:$C$17
Name Units: Master_Data!$B$8:$B$17

Sheet README
B2: Financial Dashboard Template – ครบชุด
B3: เทมเพลตข้อมูลสำหรับ Dashboard ติดตาม รายรับ / ค่าใช้จ่าย / เงินสะสม (Power BI / Tableau / Looker)
B5: 📘 โครงสร้างไฟล์
B6: Sheet: README | C6: หน้านี้ – คำแนะนำการใช้งาน
B7: Sheet: Master_Data | C7: ตั้งค่าหน่วยงาน, ปีงบประมาณ, หมวดรายรับ-รายจ่าย
B8: Sheet: รายการรายรับ | C8: บันทึกรายรับ – แผนรับ / รับจริง / ค้างรับตามสัญญา / ค้างรับจากแผน
B9: Sheet: รายการค่าใช้จ่าย | C9: บันทึกค่าใช้จ่าย – แผนจ่าย / ค่าใช้จ่ายจริง (13 หมวด)
B10: Sheet: เงินสะสมรายเดือน | C10: บันทึก CASH-CAMT, CASH-DITC + Income/Expenses รายเดือน
B11: Sheet: Dashboard_Data | C11: ข้อมูลสรุปสำหรับเชื่อม Power BI / Tableau / Pivot Chart
B13: 🎨 ความหมายของสีตัวอักษร
B14: ตัวอักษรสีน้ำเงิน | C14: เซลล์ที่ผู้ใช้กรอกข้อมูล (Input)
B15: ตัวอักษรสีดำ | C15: สูตรคำนวณ (อย่าแก้ไข)
B16: ตัวอักษรสีเขียว | C16: ลิงก์ดึงข้อมูลจากชีตอื่น (อย่าแก้ไข)
B17: พื้นหลังสีเหลือง | C17: ค่าที่ต้องปรับตั้งก่อนใช้งาน
B19: 📊 คอลัมน์หลักของแต่ละชีต
B20: รายรับ – 4 คอลัมน์หลัก | C20: แผนรับ / รับจริง / ค้างรับตามสัญญา / ค้างรับจากแผน (คำนวณอัตโนมัติ)
B21: ค่าใช้จ่าย – 2 คอลัมน์หลัก | C21: แผนจ่าย / ค่าใช้จ่ายจริง พร้อม % สำเร็จ
B22: เงินสะสม – รายเดือน | C22: Income, Expenses, CASH-CAMT, CASH-DITC ตามปีงบประมาณ (ต.ค.-ก.ย.)
B24: 🪜 ขั้นตอนการใช้งาน
B25: 1. | C25: Master_Data → ปรับปีงบประมาณ, รายชื่อหน่วยงาน, รายการหมวด
B26: 2. | C26: ‘รายการรายรับ’ → กรอกตามหน่วยงาน × หมวด พร้อมยอด แผน/จริง/สัญญา
B27: 3. | C27: ‘รายการค่าใช้จ่าย’ → กรอกตามหน่วยงาน × หมวด พร้อมยอด แผน/จริง
B28: 4. | C28: ‘เงินสะสมรายเดือน’ → กรอก Income, Expenses, CASH-CAMT, CASH-DITC แต่ละเดือน
B29: 5. | C29: ‘Dashboard_Data’ ใช้เป็น Data Source ใน Power BI (Get Data → Excel)

Sheet Master_Data
B2: Master Data – ตั้งค่าก่อนใช้งาน
B3: ปีงบประมาณ (พ.ศ.) | C3: 2569
B4: เดือนเริ่มปีงบประมาณ | C4: 10
B5: วันที่ Update ล่าสุด | C5: =TODAY() -> 46202
B7: หน่วยงาน | C7: หมวดรายรับ | D7: หมวดค่าใช้จ่าย
B8: CAMT | C8: 1.ค่าธรรมเนียมการศึกษา | D8: 1.ที่ดินและสิ่งก่อสร้าง
B9: DITC | C9: 2.รายรับ GE | D9: 2.ครุภัณฑ์
B10: RESEARCH | C10: 3.หลักสูตรร่วม | D10: 3.ค่าจ้างชั่วคราว
C11: 4.อื่นๆ เช่น ดอกเบี้ย เงินโอน จัดสรร | D11: 4.เงินสมทบพนักงานมหาวิทยาลัย
C12: 5.ค่าบริหารจัดการศูนย์ | D12: 5.เงินประจำตำแหน่งวิชาการ
C13: 6.รายได้บริการวิชาการ | D13: 6.เงินประจำตำแหน่งบริหาร
C14: 7.อื่นๆ เช่นดอกเบี้ย เงินโอน | D14: 7.ค่าตอบแทน ใช้สอยและวัสดุ
C15: 8.RESEARCH | D15: 8.ค่าสาธารณูปโภค
D16: 9.เงินอุดหนุน
D17: 10.ค่าใช้จ่ายอื่น
D18: 11.ค่าใช้จ่ายศูนย์ DITC
D19: 12.ต้นทุนโครงการบริการวิชาการ
D20: 13.วิจัย
B29: * เพิ่ม/แก้ไขรายการได้ในช่องว่าง – Dropdown ในชีตอื่นจะอัปเดตตามอัตโนมัติ

Sheet รายการรายรับ
B2: รายการรายรับ – Detail
B3: กรอกข้อมูลทีละแถว – ‘ค้างรับจากแผน’ และ ‘% สำเร็จ’ คำนวณอัตโนมัติ
B5: ลำดับ | C5: ปีงบประมาณ | D5: หน่วยงาน | E5: หมวดรายรับ | F5: รายละเอียด | G5: แผนรับ | H5: รับจริง | I5: ค้างรับตามสัญญา | J5: ค้างรับจากแผน | K5: % สำเร็จ | L5: หมายเหตุ
B6: =IF(D6="","",ROW()-5) -> 1 | C6: =IF(D6="","",Master_Data!$C$3) -> 2569 | D6: CAMT | E6: 1.ค่าธรรมเนียมการศึกษา | F6: ค่าเทอม ภาคปกติ | G6: 118940185 | H6: =51296036.47+4806220+1007300 -> 57109556 | J6: =IF(G6="","",IFERROR(G6-H6-I6,0)) -> 61830629 | K6: =IF(OR(G6="",G6=0),"",H6/G6) -> 0.48015359
B7: =IF(D7="","",ROW()-5) -> 2 | C7: =IF(D7="","",Master_Data!$C$3) -> 2569 | D7: CAMT | E7: 2.รายรับ GE | F7: รายรับวิชา GE | G7: 1200000 | H7: 0 | J7: =IF(G7="","",IFERROR(G7-H7-I7,0)) -> 1200000 | K7: =IF(OR(G7="",G7=0),"",H7/G7) -> 0
B8: =IF(D8="","",ROW()-5) -> 3 | C8: =IF(D8="","",Master_Data!$C$3) -> 2569 | D8: CAMT | E8: 3.หลักสูตรร่วม | F8: หลักสูตรร่วม | G8: 2090000 | H8: 500000 | J8: =IF(G8="","",IFERROR(G8-H8-I8,0)) -> 1590000 | K8: =IF(OR(G8="",G8=0),"",H8/G8) -> 0.23923445
B9: =IF(D9="","",ROW()-5) -> 4 | C9: =IF(D9="","",Master_Data!$C$3) -> 2569 | D9: CAMT | E9: 4.อื่นๆ เช่น ดอกเบี้ย เงินโอน จัดสรร | F9: ดอกเบี้ย/จัดสรร | G9: 4627281.4 | H9: =3572376.17+1054905.23 -> 4627281.4 | J9: =IF(G9="","",IFERROR(G9-H9-I9,0)) -> 0 | K9: =IF(OR(G9="",G9=0),"",H9/G9) -> 1
B10: =IF(D10="","",ROW()-5) -> 5 | C10: =IF(D10="","",Master_Data!$C$3) -> 2569 | D10: DITC | E10: 5.ค่าบริหารจัดการศูนย์ | F10: ค่าบริหารจัดการศูนย์ | G10: 5700000 | H10: 964448.65 | J10: =IF(G10="","",IFERROR(G10-H10-I10,0)) -> 4735551.3 | K10: =IF(OR(G10="",G10=0),"",H10/G10) -> 0.16920152
B11: =IF(D11="","",ROW()-5) -> 6 | C11: =IF(D11="","",Master_Data!$C$3) -> 2569 | D11: DITC | E11: 6.รายได้บริการวิชาการ | F11: รายได้ค่าบริการวิชาการ | G11: 51300000 | H11: 13962422 | I11: =22968748.07-H11 -> 9006326 | J11: =IF(G11="","",IFERROR(G11-H11-I11,0)) -> 28331252 | K11: =IF(OR(G11="",G11=0),"",H11/G11) -> 0.27217197
B12: =IF(D12="","",ROW()-5) -> 7 | C12: =IF(D12="","",Master_Data!$C$3) -> 2569 | D12: DITC | E12: 7.อื่นๆ เช่นดอกเบี้ย เงินโอน | F12: ดอกเบี้ย/เงินโอน | G12: 40000 | H12: 40000 | J12: =IF(G12="","",IFERROR(G12-H12-I12,0)) -> 0 | K12: =IF(OR(G12="",G12=0),"",H12/G12) -> 1
B13: =IF(D13="","",ROW()-5) -> 8 | C13: =IF(D13="","",Master_Data!$C$3) -> 2569 | D13: RESEARCH | E13: 8.RESEARCH | F13: รายได้ค่าบริการวิชาการ | G13: 15000000 | H13: =2112000+200000 -> 2312000 | I13: =4080000-2112000 -> 1968000 | J13: =IF(G13="","",IFERROR(G13-H13-I13,0)) -> 10720000 | K13: =IF(OR(G13="",G13=0),"",H13/G13) -> 0.15413333
B14: =IF(D14="","",ROW()-5) | C14: =IF(D14="","",Master_Data!$C$3) | J14: =IF(G14="","",IFERROR(G14-H14-I14,0)) | K14: =IF(OR(G14="",G14=0),"",H14/G14)
B15: =IF(D15="","",ROW()-5) | C15: =IF(D15="","",Master_Data!$C$3) | J15: =IF(G15="","",IFERROR(G15-H15-I15,0)) | K15: =IF(OR(G15="",G15=0),"",H15/G15)
B16: =IF(D16="","",ROW()-5) | C16: =IF(D16="","",Master_Data!$C$3) | J16: =IF(G16="","",IFERROR(G16-H16-I16,0)) | K16: =IF(OR(G16="",G16=0),"",H16/G16)
B17: =IF(D17="","",ROW()-5) | C17: =IF(D17="","",Master_Data!$C$3) | J17: =IF(G17="","",IFERROR(G17-H17-I17,0)) | K17: =IF(OR(G17="",G17=0),"",H17/G17)
B18: =IF(D18="","",ROW()-5) | C18: =IF(D18="","",Master_Data!$C$3) | J18: =IF(G18="","",IFERROR(G18-H18-I18,0)) | K18: =IF(OR(G18="",G18=0),"",H18/G18)
B19: =IF(D19="","",ROW()-5) | C19: =IF(D19="","",Master_Data!$C$3) | J19: =IF(G19="","",IFERROR(G19-H19-I19,0)) | K19: =IF(OR(G19="",G19=0),"",H19/G19)
B20: =IF(D20="","",ROW()-5) | C20: =IF(D20="","",Master_Data!$C$3) | J20: =IF(G20="","",IFERROR(G20-H20-I20,0)) | K20: =IF(OR(G20="",G20=0),"",H20/G20)
B21: =IF(D21="","",ROW()-5) | C21: =IF(D21="","",Master_Data!$C$3) | J21: =IF(G21="","",IFERROR(G21-H21-I21,0)) | K21: =IF(OR(G21="",G21=0),"",H21/G21)
B22: =IF(D22="","",ROW()-5) | C22: =IF(D22="","",Master_Data!$C$3) | J22: =IF(G22="","",IFERROR(G22-H22-I22,0)) | K22: =IF(OR(G22="",G22=0),"",H22/G22)
B23: =IF(D23="","",ROW()-5) | C23: =IF(D23="","",Master_Data!$C$3) | J23: =IF(G23="","",IFERROR(G23-H23-I23,0)) | K23: =IF(OR(G23="",G23=0),"",H23/G23)
B24: =IF(D24="","",ROW()-5) | C24: =IF(D24="","",Master_Data!$C$3) | J24: =IF(G24="","",IFERROR(G24-H24-I24,0)) | K24: =IF(OR(G24="",G24=0),"",H24/G24)
B25: =IF(D25="","",ROW()-5) | C25: =IF(D25="","",Master_Data!$C$3) | J25: =IF(G25="","",IFERROR(G25-H25-I25,0)) | K25: =IF(OR(G25="",G25=0),"",H25/G25)
... B204: =IF(D204="","",ROW()-5) | C204: =IF(D204="","",Master_Data!$C$3) | J204: =IF(G204="","",IFERROR(G204-H204-I204,0)) | K204: =IF(OR(G204="",G204=0),"",H204/G204)
B205: รวม | G205: =SUM(G6:G204) -> 1.9889747e+08 | H205: =SUM(H6:H204) -> 79515709 | I205: =SUM(I6:I204) -> 10974326 | J205: =SUM(J6:J204) -> 1.0840743e+08 | K205: =IF(G205=0,0,H205/G205) -> 0.39978241

Sheet รายการค่าใช้จ่าย
B2: รายการค่าใช้จ่าย – Detail
B3: กรอกข้อมูลทีละแถว – ‘คงเหลือ’ และ ‘% ใช้จริง’ คำนวณอัตโนมัติ
B5: ลำดับ | C5: ปีงบประมาณ | D5: หน่วยงาน | E5: หมวดค่าใช้จ่าย | F5: รายละเอียด | G5: แผนจ่าย | H5: ค่าใช้จ่ายจริง | I5: คงเหลือ | J5: % ใช้จริง | K5: หมายเหตุ
B6: =IF(D6="","",ROW()-5) -> 1 | C6: =IF(D6="","",Master_Data!$C$3) -> 2569 | D6: CAMT | E6: 1.ที่ดินและสิ่งก่อสร้าง | F6: ปรับปรุงอาคาร | G6: 5000000 | H6: 536651 | I6: =IF(G6="","",G6-H6) -> 4463349 | J6: =IF(OR(G6="",G6=0),"",H6/G6) -> 0.1073302
B7: =IF(D7="","",ROW()-5) -> 2 | C7: =IF(D7="","",Master_Data!$C$3) -> 2569 | D7: CAMT | E7: 2.ครุภัณฑ์ | F7: จัดซื้อครุภัณฑ์ | G7: 2281000 | H7: 1633133.5 | I7: =IF(G7="","",G7-H7) -> 647866.5 | J7: =IF(OR(G7="",G7=0),"",H7/G7) -> 0.7159726
B8: =IF(D8="","",ROW()-5) -> 3 | C8: =IF(D8="","",Master_Data!$C$3) -> 2569 | D8: CAMT | E8: 3.ค่าจ้างชั่วคราว | F8: ค่าจ้างชั่วคราว | G8: 13923800 | H8: 6386316 | I8: =IF(G8="","",G8-H8) -> 7537484 | J8: =IF(OR(G8="",G8=0),"",H8/G8) -> 0.45866186
B9: =IF(D9="","",ROW()-5) -> 4 | C9: =IF(D9="","",Master_Data!$C$3) -> 2569 | D9: CAMT | E9: 4.เงินสมทบพนักงานมหาวิทยาลัย | F9: เงินสมทบ | G9: 3589000 | H9: 2871989.1 | I9: =IF(G9="","",G9-H9) -> 717010.93 | J9: =IF(OR(G9="",G9=0),"",H9/G9) -> 0.80021986
B10: =IF(D10="","",ROW()-5) -> 5 | C10: =IF(D10="","",Master_Data!$C$3) -> 2569 | D10: CAMT | E10: 5.เงินประจำตำแหน่งวิชาการ | F10: เงินตำแหน่งวิชาการ | G10: 3886800 | H10: 3454521.9 | I10: =IF(G10="","",G10-H10) -> 432278.06 | J10: =IF(OR(G10="",G10=0),"",H10/G10) -> 0.88878305
B11: =IF(D11="","",ROW()-5) -> 6 | C11: =IF(D11="","",Master_Data!$C$3) -> 2569 | D11: CAMT | E11: 6.เงินประจำตำแหน่งบริหาร | F11: เงินตำแหน่งบริหาร | G11: 1417200 | H11: 1128400 | I11: =IF(G11="","",G11-H11) -> 288800 | J11: =IF(OR(G11="",G11=0),"",H11/G11) -> 0.79621789
B12: =IF(D12="","",ROW()-5) -> 7 | C12: =IF(D12="","",Master_Data!$C$3) -> 2569 | D12: CAMT | E12: 7.ค่าตอบแทน ใช้สอยและวัสดุ | F12: ตอบแทน-ใช้สอย-วัสดุ | G12: 35358600 | H12: 17125152 | I12: =IF(G12="","",G12-H12) -> 18233448 | J12: =IF(OR(G12="",G12=0),"",H12/G12) -> 0.48432777
B13: =IF(D13="","",ROW()-5) -> 8 | C13: =IF(D13="","",Master_Data!$C$3) -> 2569 | D13: CAMT | E13: 8.ค่าสาธารณูปโภค | F13: ค่าน้ำ-ไฟ-อินเทอร์เน็ต | G13: 3374000 | H13: 555254.04 | I13: =IF(G13="","",G13-H13) -> 2818746 | J13: =IF(OR(G13="",G13=0),"",H13/G13) -> 0.16456848
B14: =IF(D14="","",ROW()-5) -> 9 | C14: =IF(D14="","",Master_Data!$C$3) -> 2569 | D14: CAMT | E14: 9.เงินอุดหนุน | F14: เงินอุดหนุน | G14: 33660976 | H14: 12303670 | I14: =IF(G14="","",G14-H14) -> 21357306 | J14: =IF(OR(G14="",G14=0),"",H14/G14) -> 0.36551732
B15: =IF(D15="","",ROW()-5) -> 10 | C15: =IF(D15="","",Master_Data!$C$3) -> 2569 | D15: CAMT | E15: 10.ค่าใช้จ่ายอื่น | F15: ค่าใช้จ่ายอื่น ๆ | G15: 7500000 | H15: 0 | I15: =IF(G15="","",G15-H15) -> 7500000 | J15: =IF(OR(G15="",G15=0),"",H15/G15) -> 0
B16: =IF(D16="","",ROW()-5) -> 11 | C16: =IF(D16="","",Master_Data!$C$3) -> 2569 | D16: DITC | E16: 11.ค่าใช้จ่ายศูนย์ DITC | F16: ค่าใช้จ่ายศูนย์ | G16: 2168000 | H16: 501060.05 | I16: =IF(G16="","",G16-H16) -> 1666939.9 | J16: =IF(OR(G16="",G16=0),"",H16/G16) -> 0.23111626
B17: =IF(D17="","",ROW()-5) -> 12 | C17: =IF(D17="","",Master_Data!$C$3) -> 2569 | D17: DITC | E17: 12.ต้นทุนโครงการบริการวิชาการ | F17: ต้นทุนโครงการ | G17: 49500000 | H17: 8723875.3 | I17: =IF(G17="","",G17-H17) -> 40776125 | J17: =IF(OR(G17="",G17=0),"",H17/G17) -> 0.1762399
B18: =IF(D18="","",ROW()-5) -> 13 | C18: =IF(D18="","",Master_Data!$C$3) -> 2569 | D18: RESEARCH | E18: 13.วิจัย | F18: ทุนวิจัย | G18: 15000000 | H18: 1031172.8 | I18: =IF(G18="","",G18-H18) -> 13968827 | J18: =IF(OR(G18="",G18=0),"",H18/G18) -> 0.068744851
B19: =IF(D19="","",ROW()-5) | C19: =IF(D19="","",Master_Data!$C$3) | I19: =IF(G19="","",G19-H19) | J19: =IF(OR(G19="",G19=0),"",H19/G19)
B20: =IF(D20="","",ROW()-5) | C20: =IF(D20="","",Master_Data!$C$3) | I20: =IF(G20="","",G20-H20) | J20: =IF(OR(G20="",G20=0),"",H20/G20)
B21: =IF(D21="","",ROW()-5) | C21: =IF(D21="","",Master_Data!$C$3) | I21: =IF(G21="","",G21-H21) | J21: =IF(OR(G21="",G21=0),"",H21/G21)
B22: =IF(D22="","",ROW()-5) | C22: =IF(D22="","",Master_Data!$C$3) | I22: =IF(G22="","",G22-H22) | J22: =IF(OR(G22="",G22=0),"",H22/G22)
B23: =IF(D23="","",ROW()-5) | C23: =IF(D23="","",Master_Data!$C$3) | I23: =IF(G23="","",G23-H23) | J23: =IF(OR(G23="",G23=0),"",H23/G23)
B24: =IF(D24="","",ROW()-5) | C24: =IF(D24="","",Master_Data!$C$3) | I24: =IF(G24="","",G24-H24) | J24: =IF(OR(G24="",G24=0),"",H24/G24)
B25: =IF(D25="","",ROW()-5) | C25: =IF(D25="","",Master_Data!$C$3) | I25: =IF(G25="","",G25-H25) | J25: =IF(OR(G25="",G25=0),"",H25/G25)
B26: =IF(D26="","",ROW()-5) | C26: =IF(D26="","",Master_Data!$C$3) | I26: =IF(G26="","",G26-H26) | J26: =IF(OR(G26="",G26=0),"",H26/G26)
B27: =IF(D27="","",ROW()-5) | C27: =IF(D27="","",Master_Data!$C$3) | I27: =IF(G27="","",G27-H27) | J27: =IF(OR(G27="",G27=0),"",H27/G27)
B28: =IF(D28="","",ROW()-5) | C28: =IF(D28="","",Master_Data!$C$3) | I28: =IF(G28="","",G28-H28) | J28: =IF(OR(G28="",G28=0),"",H28/G28)
B29: =IF(D29="","",ROW()-5) | C29: =IF(D29="","",Master_Data!$C$3) | I29: =IF(G29="","",G29-H29) | J29: =IF(OR(G29="",G29=0),"",H29/G29)
B30: =IF(D30="","",ROW()-5) | C30: =IF(D30="","",Master_Data!$C$3) | I30: =IF(G30="","",G30-H30) | J30: =IF(OR(G30="",G30=0),"",H30/G30)
... B205: =IF(D205="","",ROW()-5) | C205: =IF(D205="","",Master_Data!$C$3) | I205: =IF(G205="","",G205-H205) | J205: =IF(OR(G205="",G205=0),"",H205/G205)
B206: รวม | G206: =SUM(G6:G205) -> 176659376 | H206: =SUM(H6:H205) -> 56251195 | I206: =SUM(I6:I205) -> 1.2040818e+08 | J206: =IF(G206=0,0,H206/G206) -> 0.31841613

Sheet เงินสะสมรายเดือน
B2: เงินสะสมรายเดือน – Cash Position
B3: กรอก Income, Expenses และ CASH-CAMT, CASH-DITC ของแต่ละเดือน (ปีงบประมาณ ต.ค.-ก.ย.)
B4: ปีงบประมาณ | C4: =Master_Data!C3 -> 2569
B6: เลขเดือน | C6: เดือน | D6: Income (รายรับ) | E6: Expenses (รายจ่าย) | F6: CASH-CAMT | G6: CASH-DITC | H6: Net Cash Flow | I6: Cash รวม
B7: 10 | C7: ตุลาคม | D7: 6975742 | E7: 13400251 | F7: 1.4439341e+08 | G7: 27674990 | H7: =D7-E7 -> -6424509.4 | I7: =F7+G7 -> 1.720684e+08
B8: 11 | C8: พฤศจิกายน | D8: 6865514.4 | E8: 17135897 | F8: 1.3427744e+08 | G8: 27520574 | H8: =D8-E8 -> -10270383 | I8: =F8+G8 -> 1.6179801e+08
B9: 12 | C9: ธันวาคม | D9: 5731449.7 | E9: 12260581 | F9: 1.2515808e+08 | G9: 30110800 | H9: =D9-E9 -> -6529131 | I9: =F9+G9 -> 1.5526888e+08
B10: 1 | C10: มกราคม | D10: 14499882 | E10: 15364980 | F10: 1.2494432e+08 | G10: 29459464 | H10: =D10-E10 -> -865098.64 | I10: =F10+G10 -> 1.5440378e+08
B11: 2 | C11: กุมภาพันธ์ | D11: 4235099.6 | E11: 9296265.4 | F11: 1.1998762e+08 | G11: 29354999 | H11: =D11-E11 -> -5061165.9 | I11: =F11+G11 -> 1.4934262e+08
B12: 3 | C12: มีนาคม | D12: 25255972 | E12: 10838931 | F12: 1.3458926e+08 | G12: 29170400 | H12: =D12-E12 -> 14417041 | I12: =F12+G12 -> 1.6375966e+08
B13: 4 | C13: เมษายน | D13: 21050414 | E13: 5892404.5 | F13: 1.4908776e+08 | G13: 29829907 | H13: =D13-E13 -> 15158009 | I13: =F13+G13 -> 1.7891767e+08
B14: 5 | C14: พฤษภาคม | D14: 15109798 | E14: 15983680 | F14: 1.4915418e+08 | G14: 28889603 | H14: =D14-E14 -> -873882.44 | I14: =F14+G14 -> 1.7804379e+08
B15: 6 | C15: มิถุนายน | D15: =3900000+2273595.28 -> 6173595.3 | E15: 15000000 | F15: 1.3366586e+08 | G15: 32577550 | H15: =D15-E15 -> -8826404.7 | I15: =F15+G15 -> 1.6624341e+08
B16: 7 | C16: กรกฎาคม | D16: 20000000 | E16: 12000000 | F16: 1.285839e+08 | G16: 42035394 | H16: =D16-E16 -> 8000000 | I16: =F16+G16 -> 1.7061929e+08
B17: 8 | C17: สิงหาคม | D17: 4000000 | E17: 10000000 | F17: 1.1825958e+08 | G17: 43002049 | H17: =D17-E17 -> -6000000 | I17: =F17+G17 -> 1.6126163e+08
B18: 9 | C18: กันยายน | D18: 54000000 | E18: =10000000+14486384.8 -> 24486385 | F18: 1.499518e+08 | G18: 41891872 | H18: =D18-E18 -> 29513615 | I18: =F18+G18 -> 1.9184367e+08
B19: รวมทั้งปี | D19: =SUM(D7:D18) -> 1.8389747e+08 | E19: =SUM(E7:E18) -> 161659376 | F19: =F18 -> 1.499518e+08 | G19: =G18 -> 41891872 | H19: =D19-E19 -> 22238090 | I19: =F19+G19 -> 1.9184367e+08

Sheet Dashboard_Data
B2: Dashboard Data – แหล่งข้อมูลรวมสำหรับ Power BI / Tableau
B4: KPI Summary – รายรับ
B5: Metric | C5: Value | D5: Format
B6: แผนรับรวม | C6: =SUM(รายการรายรับ!G6:G204) -> 1.9889747e+08 | D6: Currency
B7: รับจริงรวม | C7: =SUM(รายการรายรับ!H6:H204) -> 79515709 | D7: Currency
B8: ค้างรับตามสัญญา | C8: =SUM(รายการรายรับ!I6:I204) -> 10974326 | D8: Currency
B9: ค้างรับจากแผน | C9: =SUM(รายการรายรับ!J6:J204) -> 1.0840743e+08 | D9: Currency
B10: % สำเร็จรายรับ | C10: =IF(SUM(รายการรายรับ!G6:G204)=0,0,SUM(รายการรายรับ!H6:H204)/SUM(รายการรายรับ!G6:G204)) -> 0.39978241 | D10: Percent
B12: KPI Summary – ค่าใช้จ่าย
B13: Metric | C13: Value | D13: Format
B14: แผนจ่ายรวม | C14: =SUM(รายการค่าใช้จ่าย!G6:G205) -> 176659376 | D14: Currency
B15: ค่าใช้จ่ายรวม | C15: =SUM(รายการค่าใช้จ่าย!H6:H205) -> 56251195 | D15: Currency
B16: คงเหลือรวม | C16: =SUM(รายการค่าใช้จ่าย!G6:G205)-SUM(รายการค่าใช้จ่าย!H6:H205) -> 1.2040818e+08 | D16: Currency
B17: % ใช้จริง | C17: =IF(SUM(รายการค่าใช้จ่าย!G6:G205)=0,0,SUM(รายการค่าใช้จ่าย!H6:H205)/SUM(รายการค่าใช้จ่าย!G6:G205)) -> 0.31841613 | D17: Percent
B19: รายรับตามหน่วยงาน × หมวด
B20: หน่วยงาน | C20: หมวดรายรับ | D20: แผนรับ | E20: รับจริง | F20: ค้างรับตามสัญญา | G20: ค้างรับจากแผน
B21: CAMT | C21: 1.ค่าธรรมเนียมการศึกษา | D21: =SUMIFS(รายการรายรับ!G6:G204,รายการรายรับ!D6:D204,B21,รายการรายรับ!E6:E204,C21) -> 118940185 | E21: =SUMIFS(รายการรายรับ!H6:H204,รายการรายรับ!D6:D204,B21,รายการรายรับ!E6:E204,C21) -> 57109556 | F21: =SUMIFS(รายการรายรับ!I6:I204,รายการรายรับ!D6:D204,B21,รายการรายรับ!E6:E204,C21) -> 0 | G21: =SUMIFS(รายการรายรับ!J6:J204,รายการรายรับ!D6:D204,B21,รายการรายรับ!E6:E204,C21) -> 61830629
B22: CAMT | C22: 2.รายรับ GE | D22: =SUMIFS(รายการรายรับ!G6:G204,รายการรายรับ!D6:D204,B22,รายการรายรับ!E6:E204,C22) -> 1200000 | E22: =SUMIFS(รายการรายรับ!H6:H204,รายการรายรับ!D6:D204,B22,รายการรายรับ!E6:E204,C22) -> 0 | F22: =SUMIFS(รายการรายรับ!I6:I204,รายการรายรับ!D6:D204,B22,รายการรายรับ!E6:E204,C22) -> 0 | G22: =SUMIFS(รายการรายรับ!J6:J204,รายการรายรับ!D6:D204,B22,รายการรายรับ!E6:E204,C22) -> 1200000
B23: CAMT | C23: 3.หลักสูตรร่วม | D23: =SUMIFS(รายการรายรับ!G6:G204,รายการรายรับ!D6:D204,B23,รายการรายรับ!E6:E204,C23) -> 2090000 | E23: =SUMIFS(รายการรายรับ!H6:H204,รายการรายรับ!D6:D204,B23,รายการรายรับ!E6:E204,C23) -> 500000 | F23: =SUMIFS(รายการรายรับ!I6:I204,รายการรายรับ!D6:D204,B23,รายการรายรับ!E6:E204,C23) -> 0 | G23: =SUMIFS(รายการรายรับ!J6:J204,รายการรายรับ!D6:D204,B23,รายการรายรับ!E6:E204,C23) -> 1590000
B24: CAMT | C24: 4.อื่นๆ เช่น ดอกเบี้ย เงินโอน จัดสรร | D24: =SUMIFS(รายการรายรับ!G6:G204,รายการรายรับ!D6:D204,B24,รายการรายรับ!E6:E204,C24) -> 4627281.4 | E24: =SUMIFS(รายการรายรับ!H6:H204,รายการรายรับ!D6:D204,B24,รายการรายรับ!E6:E204,C24) -> 4627281.4 | F24: =SUMIFS(รายการรายรับ!I6:I204,รายการรายรับ!D6:D204,B24,รายการรายรับ!E6:E204,C24) -> 0 | G24: =SUMIFS(รายการรายรับ!J6:J204,รายการรายรับ!D6:D204,B24,รายการรายรับ!E6:E204,C24) -> 0
B25: DITC | C25: 1.ค่าธรรมเนียมการศึกษา | D25: =SUMIFS(รายการรายรับ!G6:G204,รายการรายรับ!D6:D204,B25,รายการรายรับ!E6:E204,C25) -> 0 | E25: =SUMIFS(รายการรายรับ!H6:H204,รายการรายรับ!D6:D204,B25,รายการรายรับ!E6:E204,C25) -> 0 | F25: =SUMIFS(รายการรายรับ!I6:I204,รายการรายรับ!D6:D204,B25,รายการรายรับ!E6:E204,C25) -> 0 | G25: =SUMIFS(รายการรายรับ!J6:J204,รายการรายรับ!D6:D204,B25,รายการรายรับ!E6:E204,C25) -> 0
B26: DITC | C26: 2.รายรับ GE | D26: =SUMIFS(รายการรายรับ!G6:G204,รายการรายรับ!D6:D204,B26,รายการรายรับ!E6:E204,C26) -> 0 | E26: =SUMIFS(รายการรายรับ!H6:H204,รายการรายรับ!D6:D204,B26,รายการรายรับ!E6:E204,C26) -> 0 | F26: =SUMIFS(รายการรายรับ!I6:I204,รายการรายรับ!D6:D204,B26,รายการรายรับ!E6:E204,C26) -> 0 | G26: =SUMIFS(รายการรายรับ!J6:J204,รายการรายรับ!D6:D204,B26,รายการรายรับ!E6:E204,C26) -> 0
B27: DITC | C27: 3.หลักสูตรร่วม | D27: =SUMIFS(รายการรายรับ!G6:G204,รายการรายรับ!D6:D204,B27,รายการรายรับ!E6:E204,C27) -> 0 | E27: =SUMIFS(รายการรายรับ!H6:H204,รายการรายรับ!D6:D204,B27,รายการรายรับ!E6:E204,C27) -> 0 | F27: =SUMIFS(รายการรายรับ!I6:I204,รายการรายรับ!D6:D204,B27,รายการรายรับ!E6:E204,C27) -> 0 | G27: =SUMIFS(รายการรายรับ!J6:J204,รายการรายรับ!D6:D204,B27,รายการรายรับ!E6:E204,C27) -> 0
B28: DITC | C28: 4.อื่นๆ เช่น ดอกเบี้ย เงินโอน จัดสรร | D28: =SUMIFS(รายการรายรับ!G6:G204,รายการรายรับ!D6:D204,B28,รายการรายรับ!E6:E204,C28) -> 0 | E28: =SUMIFS(รายการรายรับ!H6:H204,รายการรายรับ!D6:D204,B28,รายการรายรับ!E6:E204,C28) -> 0 | F28: =SUMIFS(รายการรายรับ!I6:I204,รายการรายรับ!D6:D204,B28,รายการรายรับ!E6:E204,C28) -> 0 | G28: =SUMIFS(รายการรายรับ!J6:J204,รายการรายรับ!D6:D204,B28,รายการรายรับ!E6:E204,C28) -> 0
B29: RESEARCH | C29: 1.ค่าธรรมเนียมการศึกษา | D29: =SUMIFS(รายการรายรับ!G6:G204,รายการรายรับ!D6:D204,B29,รายการรายรับ!E6:E204,C29) -> 0 | E29: =SUMIFS(รายการรายรับ!H6:H204,รายการรายรับ!D6:D204,B29,รายการรายรับ!E6:E204,C29) -> 0 | F29: =SUMIFS(รายการรายรับ!I6:I204,รายการรายรับ!D6:D204,B29,รายการรายรับ!E6:E204,C29) -> 0 | G29: =SUMIFS(รายการรายรับ!J6:J204,รายการรายรับ!D6:D204,B29,รายการรายรับ!E6:E204,C29) -> 0
B30: RESEARCH | C30: 2.รายรับ GE | D30: =SUMIFS(รายการรายรับ!G6:G204,รายการรายรับ!D6:D204,B30,รายการรายรับ!E6:E204,C30) -> 0 | E30: =SUMIFS(รายการรายรับ!H6:H204,รายการรายรับ!D6:D204,B30,รายการรายรับ!E6:E204,C30) -> 0 | F30: =SUMIFS(รายการรายรับ!I6:I204,รายการรายรับ!D6:D204,B30,รายการรายรับ!E6:E204,C30) -> 0 | G30: =SUMIFS(รายการรายรับ!J6:J204,รายการรายรับ!D6:D204,B30,รายการรายรับ!E6:E204,C30) -> 0
B31: RESEARCH | C31: 3.หลักสูตรร่วม | D31: =SUMIFS(รายการรายรับ!G6:G204,รายการรายรับ!D6:D204,B31,รายการรายรับ!E6:E204,C31) -> 0 | E31: =SUMIFS(รายการรายรับ!H6:H204,รายการรายรับ!D6:D204,B31,รายการรายรับ!E6:E204,C31) -> 0 | F31: =SUMIFS(รายการรายรับ!I6:I204,รายการรายรับ!D6:D204,B31,รายการรายรับ!E6:E204,C31) -> 0 | G31: =SUMIFS(รายการรายรับ!J6:J204,รายการรายรับ!D6:D204,B31,รายการรายรับ!E6:E204,C31) -> 0
B32: RESEARCH | C32: 4.อื่นๆ เช่น ดอกเบี้ย เงินโอน จัดสรร | D32: =SUMIFS(รายการรายรับ!G6:G204,รายการรายรับ!D6:D204,B32,รายการรายรับ!E6:E204,C32) -> 0 | E32: =SUMIFS(รายการรายรับ!H6:H204,รายการรายรับ!D6:D204,B32,รายการรายรับ!E6:E204,C32) -> 0 | F32: =SUMIFS(รายการรายรับ!I6:I204,รายการรายรับ!D6:D204,B32,รายการรายรับ!E6:E204,C32) -> 0 | G32: =SUMIFS(รายการรายรับ!J6:J204,รายการรายรับ!D6:D204,B32,รายการรายรับ!E6:E204,C32) -> 0
B34: ค่าใช้จ่ายตามหน่วยงาน × หมวด
B35: หน่วยงาน | C35: หมวดค่าใช้จ่าย | D35: แผนจ่าย | E35: ค่าใช้จ่ายจริง | F35: % ใช้จริง
B36: CAMT | C36: 1.ที่ดินและสิ่งก่อสร้าง | D36: =SUMIFS(รายการค่าใช้จ่าย!G6:G205,รายการค่าใช้จ่าย!D6:D205,B36,รายการค่าใช้จ่าย!E6:E205,C36) -> 5000000 | E36: =SUMIFS(รายการค่าใช้จ่าย!H6:H205,รายการค่าใช้จ่าย!D6:D205,B36,รายการค่าใช้จ่าย!E6:E205,C36) -> 536651 | F36: =IF(D36=0,0,E36/D36) -> 0.1073302
B37: CAMT | C37: 2.ครุภัณฑ์ | D37: =SUMIFS(รายการค่าใช้จ่าย!G6:G205,รายการค่าใช้จ่าย!D6:D205,B37,รายการค่าใช้จ่าย!E6:E205,C37) -> 2281000 | E37: =SUMIFS(รายการค่าใช้จ่าย!H6:H205,รายการค่าใช้จ่าย!D6:D205,B37,รายการค่าใช้จ่าย!E6:E205,C37) -> 1633133.5 | F37: =IF(D37=0,0,E37/D37) -> 0.7159726
B38: CAMT | C38: 3.ค่าจ้างชั่วคราว | D38: =SUMIFS(รายการค่าใช้จ่าย!G6:G205,รายการค่าใช้จ่าย!D6:D205,B38,รายการค่าใช้จ่าย!E6:E205,C38) -> 13923800 | E38: =SUMIFS(รายการค่าใช้จ่าย!H6:H205,รายการค่าใช้จ่าย!D6:D205,B38,รายการค่าใช้จ่าย!E6:E205,C38) -> 6386316 | F38: =IF(D38=0,0,E38/D38) -> 0.45866186
B39: CAMT | C39: 4.เงินสมทบพนักงานมหาวิทยาลัย | D39: =SUMIFS(รายการค่าใช้จ่าย!G6:G205,รายการค่าใช้จ่าย!D6:D205,B39,รายการค่าใช้จ่าย!E6:E205,C39) -> 3589000 | E39: =SUMIFS(รายการค่าใช้จ่าย!H6:H205,รายการค่าใช้จ่าย!D6:D205,B39,รายการค่าใช้จ่าย!E6:E205,C39) -> 2871989.1 | F39: =IF(D39=0,0,E39/D39) -> 0.80021986
B40: CAMT | C40: 5.เงินประจำตำแหน่งวิชาการ | D40: =SUMIFS(รายการค่าใช้จ่าย!G6:G205,รายการค่าใช้จ่าย!D6:D205,B40,รายการค่าใช้จ่าย!E6:E205,C40) -> 3886800 | E40: =SUMIFS(รายการค่าใช้จ่าย!H6:H205,รายการค่าใช้จ่าย!D6:D205,B40,รายการค่าใช้จ่าย!E6:E205,C40) -> 3454521.9 | F40: =IF(D40=0,0,E40/D40) -> 0.88878305
B41: CAMT | C41: 6.เงินประจำตำแหน่งบริหาร | D41: =SUMIFS(รายการค่าใช้จ่าย!G6:G205,รายการค่าใช้จ่าย!D6:D205,B41,รายการค่าใช้จ่าย!E6:E205,C41) -> 1417200 | E41: =SUMIFS(รายการค่าใช้จ่าย!H6:H205,รายการค่าใช้จ่าย!D6:D205,B41,รายการค่าใช้จ่าย!E6:E205,C41) -> 1128400 | F41: =IF(D41=0,0,E41/D41) -> 0.79621789
B42: CAMT | C42: 7.ค่าตอบแทน ใช้สอยและวัสดุ | D42: =SUMIFS(รายการค่าใช้จ่าย!G6:G205,รายการค่าใช้จ่าย!D6:D205,B42,รายการค่าใช้จ่าย!E6:E205,C42) -> 35358600 | E42: =SUMIFS(รายการค่าใช้จ่าย!H6:H205,รายการค่าใช้จ่าย!D6:D205,B42,รายการค่าใช้จ่าย!E6:E205,C42) -> 17125152 | F42: =IF(D42=0,0,E42/D42) -> 0.48432777
B43: CAMT | C43: 8.ค่าสาธารณูปโภค | D43: =SUMIFS(รายการค่าใช้จ่าย!G6:G205,รายการค่าใช้จ่าย!D6:D205,B43,รายการค่าใช้จ่าย!E6:E205,C43) -> 3374000 | E43: =SUMIFS(รายการค่าใช้จ่าย!H6:H205,รายการค่าใช้จ่าย!D6:D205,B43,รายการค่าใช้จ่าย!E6:E205,C43) -> 555254.04 | F43: =IF(D43=0,0,E43/D43) -> 0.16456848
B44: CAMT | C44: 9.เงินอุดหนุน | D44: =SUMIFS(รายการค่าใช้จ่าย!G6:G205,รายการค่าใช้จ่าย!D6:D205,B44,รายการค่าใช้จ่าย!E6:E205,C44) -> 33660976 | E44: =SUMIFS(รายการค่าใช้จ่าย!H6:H205,รายการค่าใช้จ่าย!D6:D205,B44,รายการค่าใช้จ่าย!E6:E205,C44) -> 12303670 | F44: =IF(D44=0,0,E44/D44) -> 0.36551732
B45: CAMT | C45: 10.ค่าใช้จ่ายอื่น | D45: =SUMIFS(รายการค่าใช้จ่าย!G6:G205,รายการค่าใช้จ่าย!D6:D205,B45,รายการค่าใช้จ่าย!E6:E205,C45) -> 7500000 | E45: =SUMIFS(รายการค่าใช้จ่าย!H6:H205,รายการค่าใช้จ่าย!D6:D205,B45,รายการค่าใช้จ่าย!E6:E205,C45) -> 0 | F45: =IF(D45=0,0,E45/D45) -> 0
...
